fill ^21 ^-3 ^13 ^21 ^1 ^13 dripstone_block
setblock ^21 ^-3 ^14 raw_iron_block
setblock ^27 ^-3 ^26 dripstone_block
setblock ^28 ^-3 ^23 dripstone_block
fill ^29 ^-3 ^24 ^30 ^-3 ^24 dripstone_block
fill ^30 ^-3 ^21 ^30 ^4 ^21 dripstone_block
fill ^21 ^-2 ^14 ^21 ^1 ^14 dripstone_block
fill ^21 ^-2 ^15 ^21 ^-1 ^15 dripstone_block
fill ^27 ^-2 ^26 ^27 ^3 ^26 dripstone_block
fill ^28 ^-2 ^23 ^28 ^2 ^23 dripstone_block
fill ^29 ^-2 ^24 ^30 ^-2 ^24 dripstone_block
fill ^18 ^-1 ^17 ^18 ^1 ^17 dripstone_block
fill ^19 ^-1 ^14 ^19 ^1 ^14 dripstone_block
fill ^19 ^-1 ^18 ^19 ^1 ^18 dripstone_block
setblock ^19 ^-1 ^21 dripstone_block
fill ^19 ^-1 ^23 ^20 ^-1 ^23 dripstone_block
fill ^20 ^-1 ^15 ^20 ^1 ^15 dripstone_block
fill ^21 ^-1 ^16 ^21 ^0 ^16 dripstone_block
fill ^24 ^-1 ^15 ^25 ^-1 ^15 dripstone_block
fill ^26 ^-1 ^21 ^26 ^0 ^21 dripstone_block
fill ^29 ^-1 ^24 ^30 ^-1 ^24 dripstone_block
fill ^16 ^0 ^18 ^16 ^2 ^18 dripstone_block
fill ^17 ^0 ^14 ^17 ^2 ^14 dripstone_block
fill ^17 ^0 ^20 ^17 ^2 ^20 dripstone_block
fill ^17 ^0 ^21 ^17 ^2 ^21 dripstone_block
fill ^18 ^0 ^15 ^20 ^0 ^15 dripstone_block
fill ^18 ^0 ^16 ^18 ^2 ^16 dripstone_block
fill ^18 ^0 ^19 ^19 ^0 ^19 dripstone_block
fill ^19 ^0 ^21 ^19 ^1 ^21 dripstone_block
fill ^19 ^0 ^23 ^20 ^0 ^23 dripstone_block
fill ^19 ^0 ^24 ^19 ^2 ^24 dripstone_block
fill ^20 ^0 ^12 ^20 ^3 ^12 dripstone_block
fill ^20 ^0 ^13 ^20 ^2 ^13 dripstone_block
fill ^20 ^0 ^14 ^20 ^2 ^14 dripstone_block
fill ^20 ^0 ^16 ^20 ^2 ^16 dripstone_block
fill ^20 ^0 ^17 ^22 ^0 ^17 dripstone_block
setblock ^20 ^0 ^24 dripstone_block
setblock ^21 ^0 ^15 magma
setblock ^21 ^0 ^21 dripstone_block
fill ^21 ^0 ^24 ^21 ^1 ^24 dripstone_block
fill ^22 ^0 ^13 ^22 ^2 ^13 dripstone_block
fill ^22 ^0 ^16 ^22 ^2 ^16 dripstone_block
fill ^22 ^0 ^23 ^22 ^1 ^23 obsidian
setblock ^22 ^0 ^25 dripstone_block
setblock ^23 ^0 ^23 dripstone_block
fill ^24 ^0 ^15 ^25 ^0 ^15 dripstone_block
fill ^24 ^0 ^16 ^25 ^0 ^16 dripstone_block
fill ^24 ^0 ^17 ^24 ^2 ^17 dripstone_block
fill ^24 ^0 ^23 ^24 ^0 ^25 dripstone_block
fill ^25 ^0 ^21 ^25 ^2 ^21 dripstone_block
fill ^25 ^0 ^23 ^28 ^0 ^23 dripstone_block
setblock ^25 ^0 ^25 dripstone_block
setblock ^26 ^0 ^24 dripstone_block
fill ^26 ^0 ^25 ^26 ^2 ^25 dripstone_block
fill ^27 ^0 ^21 ^30 ^0 ^21 dripstone_block
fill ^27 ^0 ^24 ^27 ^2 ^24 dripstone_block
setblock ^27 ^0 ^25 dripstone_block
fill ^29 ^0 ^24 ^30 ^0 ^24 dripstone_block
fill ^13 ^1 ^24 ^15 ^1 ^24 dripstone_block
fill ^14 ^1 ^18 ^19 ^1 ^18 dripstone_block
fill ^14 ^1 ^20 ^14 ^4 ^20 dripstone_block
fill ^14 ^1 ^21 ^14 ^4 ^21 dripstone_block
fill ^14 ^1 ^23 ^14 ^2 ^23 dripstone_block
fill ^14 ^1 ^25 ^14 ^2 ^25 dripstone_block
setblock ^14 ^1 ^30 dripstone_block
fill ^15 ^1 ^13 ^15 ^3 ^13 dripstone_block
fill ^15 ^1 ^22 ^16 ^1 ^22 dripstone_block
fill ^16 ^1 ^12 ^16 ^5 ^12 dripstone_block
fill ^16 ^1 ^14 ^16 ^3 ^14 dripstone_block
fill ^16 ^1 ^17 ^25 ^1 ^17 dripstone_block
fill ^16 ^1 ^20 ^16 ^3 ^20 dripstone_block
fill ^16 ^1 ^21 ^16 ^3 ^21 dripstone_block
fill ^16 ^1 ^23 ^16 ^3 ^23 dripstone_block
fill ^17 ^1 ^13 ^24 ^1 ^13 dripstone_block
fill ^17 ^1 ^15 ^20 ^1 ^15 dripstone_block
fill ^17 ^1 ^19 ^20 ^1 ^19 dripstone_block
fill ^17 ^1 ^24 ^23 ^1 ^24 dripstone_block
fill ^17 ^1 ^25 ^17 ^3 ^25 dripstone_block
fill ^18 ^1 ^12 ^20 ^1 ^12 dripstone_block
fill ^18 ^1 ^14 ^18 ^3 ^14 dripstone_block
fill ^18 ^1 ^20 ^19 ^1 ^20 dripstone_block
fill ^18 ^1 ^21 ^18 ^3 ^21 dripstone_block
fill ^18 ^1 ^22 ^19 ^1 ^22 dripstone_block
fill ^19 ^1 ^23 ^19 ^0 ^23 dripstone_block
fill ^20 ^1 ^20 ^22 ^1 ^20 obsidian
fill ^20 ^1 ^21 ^23 ^1 ^21 obsidian
fill ^20 ^1 ^22 ^23 ^1 ^22 obsidian
fill ^20 ^1 ^23 ^23 ^1 ^23 obsidian
setblock ^20 ^1 ^25 dripstone_block
setblock ^20 ^1 ^28 dripstone_block
fill ^21 ^1 ^19 ^22 ^1 ^19 obsidian
fill ^21 ^1 ^25 ^22 ^1 ^25 dripstone_block
fill ^21 ^1 ^26 ^22 ^1 ^26 dripstone_block
fill ^22 ^1 ^12 ^22 ^3 ^12 dripstone_block
fill ^22 ^1 ^14 ^22 ^3 ^14 dripstone_block
fill ^22 ^1 ^15 ^23 ^1 ^15 dripstone_block
fill ^23 ^1 ^16 ^24 ^1 ^16 dripstone_block
fill ^23 ^1 ^19 ^23 ^3 ^19 dripstone_block
setblock ^23 ^1 ^25 dripstone_block
setblock ^23 ^1 ^28 dripstone_block
fill ^24 ^1 ^15 ^25 ^1 ^15 magma
fill ^24 ^1 ^21 ^24 ^1 ^23 dripstone_block
setblock ^24 ^1 ^24 lava
fill ^24 ^1 ^25 ^28 ^1 ^25 dripstone_block
fill ^25 ^1 ^14 ^26 ^1 ^14 dripstone_block
setblock ^25 ^1 ^16 magma
fill ^25 ^1 ^19 ^25 ^3 ^19 dripstone_block
fill ^25 ^1 ^20 ^25 ^3 ^20 dripstone_block
fill ^25 ^1 ^22 ^28 ^1 ^22 dripstone_block
fill ^25 ^1 ^23 ^30 ^1 ^23 dripstone_block
fill ^25 ^1 ^24 ^30 ^1 ^24 dripstone_block
setblock ^25 ^1 ^26 dripstone_block
fill ^26 ^1 ^15 ^26 ^3 ^15 dripstone_block
fill ^26 ^1 ^16 ^26 ^3 ^16 dripstone_block
fill ^26 ^1 ^19 ^26 ^1 ^21 magma
setblock ^26 ^1 ^27 dripstone_block
fill ^27 ^1 ^20 ^28 ^1 ^20 dripstone_block
fill ^27 ^1 ^21 ^30 ^1 ^21 dripstone_block
fill ^28 ^1 ^19 ^29 ^1 ^19 dripstone_block
fill ^28 ^1 ^26 ^28 ^2 ^26 dripstone_block
fill ^12 ^2 ^23 ^18 ^2 ^23 dripstone_block
setblock ^12 ^2 ^30 dripstone_block
fill ^13 ^2 ^19 ^13 ^3 ^19 dripstone_block
fill ^13 ^2 ^24 ^19 ^2 ^24 dripstone_block
fill ^13 ^2 ^25 ^13 ^5 ^25 dripstone_block
fill ^13 ^2 ^26 ^17 ^2 ^26 dripstone_block
setblock ^13 ^2 ^30 dripstone_block
fill ^14 ^2 ^18 ^18 ^2 ^18 dripstone_block
fill ^14 ^2 ^22 ^18 ^2 ^22 dripstone_block
fill ^14 ^2 ^27 ^18 ^2 ^27 dripstone_block
fill ^14 ^2 ^28 ^14 ^4 ^28 dripstone_block
fill ^14 ^2 ^30 ^14 ^3 ^30 dripstone_block
setblock ^14 ^2 ^31 dripstone_block
fill ^15 ^2 ^14 ^15 ^4 ^14 dripstone_block
fill ^15 ^2 ^19 ^19 ^2 ^19 dripstone_block
fill ^15 ^2 ^20 ^15 ^4 ^20 dripstone_block
fill ^15 ^2 ^21 ^15 ^4 ^21 dripstone_block
fill ^15 ^2 ^25 ^17 ^2 ^25 dripstone_block
fill ^15 ^2 ^28 ^15 ^2 ^30 dripstone_block
fill ^16 ^2 ^13 ^20 ^2 ^13 dripstone_block
fill ^16 ^2 ^15 ^19 ^2 ^15 dripstone_block
fill ^16 ^2 ^17 ^17 ^2 ^17 dripstone_block
fill ^16 ^2 ^28 ^17 ^2 ^28 dripstone_block
setblock ^16 ^2 ^30 dripstone_block
fill ^17 ^2 ^12 ^22 ^2 ^12 dripstone_block
fill ^17 ^2 ^16 ^17 ^4 ^16 dripstone_block
setblock ^17 ^2 ^31 dripstone_block
fill ^18 ^2 ^20 ^18 ^3 ^20 dripstone_block
fill ^18 ^2 ^26 ^20 ^2 ^26 dripstone_block
fill ^18 ^2 ^28 ^19 ^2 ^28 dripstone_block
setblock ^18 ^2 ^30 raw_iron_block
fill ^19 ^2 ^11 ^19 ^4 ^11 dripstone_block
fill ^19 ^2 ^16 ^19 ^4 ^16 dripstone_block
fill ^19 ^2 ^17 ^26 ^2 ^17 dripstone_block
fill ^19 ^2 ^20 ^20 ^2 ^20 obsidian
fill ^19 ^2 ^21 ^19 ^3 ^21 obsidian
fill ^19 ^2 ^22 ^19 ^4 ^22 obsidian
fill ^19 ^2 ^23 ^20 ^2 ^23 obsidian
fill ^19 ^2 ^25 ^28 ^2 ^25 dripstone_block
fill ^19 ^2 ^27 ^20 ^2 ^27 dripstone_block
fill ^19 ^2 ^29 ^20 ^2 ^29 dripstone_block
fill ^19 ^2 ^30 ^20 ^2 ^30 dripstone_block
fill ^20 ^2 ^18 ^27 ^2 ^18 dripstone_block
fill ^20 ^2 ^19 ^22 ^2 ^19 obsidian
fill ^20 ^2 ^24 ^23 ^2 ^24 obsidian
fill ^20 ^2 ^28 ^20 ^3 ^28 dripstone_block
fill ^21 ^2 ^26 ^22 ^2 ^26 dripstone_block
fill ^22 ^2 ^15 ^23 ^2 ^15 dripstone_block
fill ^22 ^2 ^20 ^23 ^2 ^20 obsidian
fill ^22 ^2 ^28 ^22 ^2 ^29 dripstone_block
fill ^23 ^2 ^13 ^24 ^2 ^13 dripstone_block
fill ^23 ^2 ^14 ^26 ^2 ^14 dripstone_block
fill ^23 ^2 ^16 ^24 ^2 ^16 dripstone_block
fill ^23 ^2 ^23 ^23 ^4 ^23 obsidian
fill ^23 ^2 ^26 ^23 ^2 ^27 dripstone_block
setblock ^23 ^2 ^28 dripstone_block
fill ^23 ^2 ^29 ^24 ^2 ^29 dripstone_block
fill ^24 ^2 ^20 ^24 ^4 ^20 dripstone_block
fill ^24 ^2 ^21 ^24 ^4 ^21 obsidian
fill ^24 ^2 ^22 ^24 ^3 ^22 obsidian
fill ^24 ^2 ^23 ^25 ^2 ^23 dripstone_block
fill ^24 ^2 ^27 ^25 ^2 ^27 dripstone_block
fill ^24 ^2 ^28 ^24 ^2 ^27 dripstone_block
setblock ^24 ^2 ^30 dripstone_block
fill ^25 ^2 ^22 ^30 ^2 ^22 dripstone_block
fill ^25 ^2 ^24 ^30 ^2 ^24 dripstone_block
fill ^25 ^2 ^26 ^25 ^3 ^26 dripstone_block
fill ^26 ^2 ^19 ^29 ^2 ^19 dripstone_block
setblock ^26 ^2 ^23 raw_iron_block
setblock ^26 ^2 ^26 dripstone_block
fill ^26 ^2 ^27 ^26 ^3 ^27 dripstone_block
fill ^27 ^2 ^15 ^28 ^2 ^15 dripstone_block
fill ^27 ^2 ^16 ^28 ^2 ^16 dripstone_block
fill ^27 ^2 ^20 ^29 ^2 ^20 dripstone_block
setblock ^27 ^2 ^23 dripstone_block
fill ^28 ^2 ^21 ^30 ^2 ^21 dripstone_block
fill ^29 ^2 ^23 ^31 ^2 ^23 dripstone_block
fill ^30 ^2 ^25 ^30 ^5 ^25 dripstone_block
fill ^9 ^3 ^29 ^10 ^3 ^29 dripstone_block
fill ^10 ^3 ^23 ^10 ^8 ^23 dripstone_block
fill ^10 ^3 ^25 ^10 ^7 ^25 dripstone_block
setblock ^10 ^3 ^28 dripstone_block
fill ^10 ^3 ^31 ^14 ^3 ^31 dripstone_block
setblock ^11 ^3 ^30 dripstone_block
fill ^12 ^3 ^20 ^16 ^3 ^20 dripstone_block
fill ^12 ^3 ^23 ^13 ^3 ^23 dripstone_block
fill ^12 ^3 ^24 ^12 ^6 ^24 dripstone_block
fill ^12 ^3 ^27 ^12 ^5 ^27 dripstone_block
fill ^12 ^3 ^29 ^20 ^3 ^29 dripstone_block
fill ^13 ^3 ^12 ^13 ^4 ^12 dripstone_block
fill ^13 ^3 ^21 ^13 ^5 ^21 dripstone_block
fill ^13 ^3 ^24 ^15 ^3 ^24 magma
fill ^13 ^3 ^26 ^27 ^3 ^26 dripstone_block
fill ^13 ^3 ^28 ^13 ^5 ^28 dripstone_block
fill ^13 ^3 ^30 ^13 ^4 ^30 dripstone_block
fill ^14 ^3 ^13 ^14 ^5 ^13 dripstone_block
fill ^14 ^3 ^14 ^14 ^5 ^14 dripstone_block
fill ^14 ^3 ^15 ^17 ^3 ^15 dripstone_block
fill ^14 ^3 ^16 ^14 ^5 ^16 dripstone_block
fill ^14 ^3 ^18 ^15 ^3 ^18 dripstone_block
fill ^14 ^3 ^19 ^17 ^3 ^19 dripstone_block
fill ^14 ^3 ^22 ^18 ^3 ^22 dripstone_block
setblock ^14 ^3 ^23 magma
setblock ^14 ^3 ^25 magma
fill ^14 ^3 ^27 ^27 ^3 ^27 dripstone_block
fill ^15 ^3 ^17 ^17 ^3 ^17 dripstone_block
fill ^15 ^3 ^23 ^15 ^4 ^23 dripstone_block
fill ^15 ^3 ^25 ^21 ^3 ^25 dripstone_block
fill ^15 ^3 ^28 ^22 ^3 ^28 dripstone_block
fill ^15 ^3 ^30 ^20 ^3 ^30 dripstone_block
fill ^16 ^3 ^13 ^19 ^3 ^13 dripstone_block
fill ^16 ^3 ^16 ^16 ^5 ^16 dripstone_block
fill ^16 ^3 ^24 ^18 ^3 ^24 dripstone_block
fill ^17 ^3 ^12 ^22 ^3 ^12 dripstone_block
fill ^17 ^3 ^18 ^18 ^3 ^18 dripstone_block
fill ^17 ^3 ^23 ^18 ^3 ^23 dripstone_block
fill ^17 ^3 ^31 ^17 ^6 ^31 dripstone_block
fill ^19 ^3 ^17 ^19 ^1 ^17 dripstone_block
fill ^19 ^3 ^20 ^19 ^2 ^20 obsidian
fill ^19 ^3 ^23 ^19 ^4 ^23 obsidian
fill ^19 ^3 ^24 ^23 ^3 ^24 obsidian
fill ^20 ^3 ^18 ^20 ^4 ^18 dripstone_block
fill ^20 ^3 ^19 ^22 ^3 ^19 obsidian
setblock ^21 ^3 ^18 obsidian
fill ^21 ^3 ^22 ^21 ^5 ^22 obsidian
fill ^22 ^3 ^15 ^23 ^3 ^15 dripstone_block
fill ^22 ^3 ^18 ^28 ^3 ^18 dripstone_block
setblock ^22 ^3 ^25 obsidian
fill ^22 ^3 ^29 ^26 ^3 ^29 dripstone_block
fill ^23 ^3 ^13 ^28 ^3 ^13 dripstone_block
fill ^23 ^3 ^14 ^25 ^3 ^14 dripstone_block
fill ^23 ^3 ^16 ^23 ^1 ^16 dripstone_block
fill ^23 ^3 ^17 ^23 ^3 ^13 dripstone_block
fill ^23 ^3 ^20 ^23 ^4 ^20 obsidian
fill ^23 ^3 ^21 ^23 ^5 ^21 obsidian
setblock ^23 ^3 ^25 dripstone_block
setblock ^23 ^3 ^28 magma
fill ^24 ^3 ^19 ^24 ^4 ^19 dripstone_block
fill ^24 ^3 ^23 ^25 ^3 ^23 obsidian
fill ^24 ^3 ^28 ^26 ^3 ^28 dripstone_block
fill ^24 ^3 ^30 ^28 ^3 ^30 dripstone_block
fill ^25 ^3 ^17 ^30 ^3 ^17 dripstone_block
fill ^25 ^3 ^22 ^30 ^3 ^22 dripstone_block
fill ^25 ^3 ^24 ^25 ^1 ^24 dripstone_block
fill ^26 ^3 ^12 ^26 ^5 ^12 dripstone_block
setblock ^26 ^3 ^14 raw_iron_block
fill ^26 ^3 ^19 ^29 ^3 ^19 dripstone_block
fill ^27 ^3 ^14 ^27 ^5 ^14 dripstone_block
fill ^27 ^3 ^15 ^29 ^3 ^15 dripstone_block
fill ^27 ^3 ^16 ^29 ^3 ^16 dripstone_block
fill ^27 ^3 ^20 ^29 ^3 ^20 dripstone_block
fill ^28 ^3 ^24 ^30 ^3 ^24 dripstone_block
fill ^28 ^3 ^25 ^28 ^4 ^25 dripstone_block
setblock ^28 ^3 ^26 magma
fill ^28 ^3 ^28 ^28 ^5 ^28 dripstone_block
fill ^29 ^3 ^14 ^30 ^3 ^14 dripstone_block
fill ^29 ^3 ^23 ^31 ^3 ^23 dripstone_block
fill ^31 ^3 ^15 ^32 ^3 ^15 dripstone_block
fill ^31 ^3 ^21 ^31 ^5 ^21 dripstone_block
fill ^9 ^4 ^27 ^15 ^4 ^27 dripstone_block
fill ^9 ^4 ^28 ^9 ^5 ^28 dripstone_block
fill ^9 ^4 ^29 ^28 ^4 ^29 dripstone_block
setblock ^10 ^4 ^28 lava
fill ^10 ^4 ^31 ^14 ^4 ^31 dripstone_block
fill ^11 ^4 ^25 ^11 ^6 ^25 dripstone_block
fill ^11 ^4 ^26 ^20 ^4 ^26 dripstone_block
fill ^11 ^4 ^28 ^19 ^4 ^28 dripstone_block
setblock ^11 ^4 ^30 raw_iron_block
fill ^11 ^4 ^32 ^11 ^5 ^32 dripstone_block
fill ^12 ^4 ^11 ^16 ^4 ^11 dripstone_block
fill ^12 ^4 ^12 ^12 ^6 ^12 dripstone_block
fill ^12 ^4 ^13 ^12 ^6 ^13 dripstone_block
fill ^12 ^4 ^15 ^16 ^4 ^15 dripstone_block
fill ^12 ^4 ^19 ^12 ^6 ^19 dripstone_block
fill ^12 ^4 ^20 ^15 ^4 ^20 dripstone_block
fill ^12 ^4 ^22 ^12 ^7 ^22 dripstone_block
fill ^12 ^4 ^23 ^13 ^4 ^23 dripstone_block
setblock ^12 ^4 ^30 magma
fill ^13 ^4 ^14 ^13 ^6 ^14 dripstone_block
setblock ^13 ^4 ^18 magma
setblock ^13 ^4 ^19 raw_iron_block
fill ^13 ^4 ^32 ^15 ^4 ^32 dripstone_block
fill ^14 ^4 ^12 ^17 ^4 ^12 dripstone_block
fill ^14 ^4 ^17 ^15 ^4 ^17 dripstone_block
fill ^14 ^4 ^19 ^16 ^4 ^19 dripstone_block
fill ^14 ^4 ^22 ^14 ^2 ^22 dripstone_block
setblock ^15 ^4 ^13 lava
fill ^15 ^4 ^16 ^15 ^6 ^16 dripstone_block
fill ^15 ^4 ^25 ^16 ^4 ^25 dripstone_block
fill ^15 ^4 ^30 ^21 ^4 ^30 dripstone_block
fill ^16 ^4 ^13 ^16 ^2 ^13 dripstone_block
fill ^16 ^4 ^24 ^16 ^2 ^24 dripstone_block
setblock ^16 ^4 ^27 obsidian
fill ^16 ^4 ^31 ^16 ^7 ^31 dripstone_block
fill ^17 ^4 ^22 ^17 ^4 ^23 dripstone_block
fill ^17 ^4 ^27 ^25 ^4 ^27 dripstone_block
setblock ^18 ^4 ^12 obsidian
setblock ^18 ^4 ^23 dripstone_block
fill ^18 ^4 ^25 ^19 ^4 ^25 dripstone_block
fill ^20 ^4 ^11 ^25 ^4 ^11 dripstone_block
fill ^20 ^4 ^20 ^20 ^4 ^24 obsidian
setblock ^20 ^4 ^28 magma
fill ^20 ^4 ^31 ^21 ^4 ^31 dripstone_block
fill ^21 ^4 ^19 ^22 ^4 ^19 obsidian
fill ^21 ^4 ^21 ^21 ^5 ^21 obsidian
fill ^21 ^4 ^24 ^23 ^4 ^24 obsidian
fill ^21 ^4 ^28 ^22 ^4 ^28 dripstone_block
fill ^22 ^4 ^18 ^30 ^4 ^18 dripstone_block
fill ^22 ^4 ^20 ^22 ^5 ^20 obsidian
fill ^23 ^4 ^12 ^27 ^4 ^12 dripstone_block
fill ^23 ^4 ^14 ^24 ^4 ^14 dripstone_block
fill ^23 ^4 ^22 ^23 ^5 ^22 obsidian
fill ^23 ^4 ^26 ^24 ^4 ^26 dripstone_block
fill ^24 ^4 ^23 ^24 ^3 ^23 obsidian
fill ^24 ^4 ^28 ^31 ^4 ^28 dripstone_block
fill ^24 ^4 ^30 ^28 ^4 ^30 dripstone_block
fill ^25 ^4 ^13 ^28 ^4 ^13 dripstone_block
setblock ^26 ^4 ^14 dripstone_block
fill ^26 ^4 ^17 ^30 ^4 ^17 dripstone_block
fill ^26 ^4 ^19 ^27 ^4 ^19 dripstone_block
setblock ^26 ^4 ^26 dripstone_block
fill ^27 ^4 ^15 ^32 ^4 ^15 dripstone_block
fill ^27 ^4 ^16 ^32 ^4 ^16 dripstone_block
fill ^27 ^4 ^27 ^30 ^4 ^27 dripstone_block
fill ^27 ^4 ^31 ^28 ^4 ^31 dripstone_block
fill ^29 ^4 ^14 ^30 ^4 ^14 dripstone_block
setblock ^29 ^4 ^19 obsidian
setblock ^29 ^4 ^20 dripstone_block
fill ^29 ^4 ^22 ^30 ^4 ^22 dripstone_block
fill ^29 ^4 ^24 ^30 ^4 ^24 dripstone_block
fill ^29 ^4 ^26 ^29 ^6 ^26 dripstone_block
fill ^31 ^4 ^13 ^31 ^5 ^13 dripstone_block
fill ^31 ^4 ^20 ^32 ^4 ^20 dripstone_block
fill ^31 ^4 ^23 ^32 ^4 ^23 dripstone_block
fill ^32 ^4 ^19 ^32 ^6 ^19 dripstone_block
fill ^4 ^5 ^29 ^5 ^5 ^29 dripstone_block
fill ^9 ^5 ^27 ^13 ^5 ^27 dripstone_block
fill ^9 ^5 ^29 ^11 ^5 ^29 dripstone_block
fill ^9 ^5 ^30 ^10 ^5 ^30 dripstone_block
fill ^9 ^5 ^32 ^11 ^5 ^32 dripstone_block
fill ^10 ^5 ^9 ^10 ^6 ^9 dripstone_block
fill ^10 ^5 ^12 ^10 ^7 ^12 dripstone_block
fill ^10 ^5 ^15 ^10 ^7 ^15 dripstone_block
fill ^10 ^5 ^17 ^10 ^8 ^17 dripstone_block
fill ^10 ^5 ^18 ^10 ^8 ^18 dripstone_block
fill ^10 ^5 ^20 ^10 ^8 ^20 dripstone_block
fill ^10 ^5 ^22 ^10 ^8 ^22 dripstone_block
fill ^10 ^5 ^26 ^11 ^5 ^26 dripstone_block
fill ^10 ^5 ^31 ^14 ^5 ^31 dripstone_block
fill ^11 ^5 ^28 ^13 ^5 ^28 dripstone_block
fill ^11 ^5 ^33 ^11 ^6 ^33 dripstone_block
fill ^12 ^5 ^11 ^14 ^5 ^11 dripstone_block
fill ^12 ^5 ^15 ^15 ^5 ^15 dripstone_block
fill ^12 ^5 ^20 ^13 ^5 ^20 dripstone_block
fill ^12 ^5 ^23 ^13 ^5 ^23 dripstone_block
fill ^13 ^5 ^9 ^13 ^7 ^9 dripstone_block
setblock ^13 ^5 ^12 magma
fill ^13 ^5 ^13 ^13 ^7 ^13 dripstone_block
fill ^13 ^5 ^16 ^13 ^7 ^16 dripstone_block
fill ^13 ^5 ^17 ^15 ^5 ^17 dripstone_block
fill ^13 ^5 ^18 ^13 ^7 ^18 dripstone_block
fill ^13 ^5 ^22 ^13 ^6 ^22 dripstone_block
setblock ^13 ^5 ^26 dripstone_block
fill ^13 ^5 ^29 ^14 ^5 ^29 dripstone_block
fill ^13 ^5 ^32 ^14 ^5 ^32 dripstone_block
fill ^13 ^5 ^33 ^13 ^8 ^33 dripstone_block
fill ^14 ^5 ^12 ^17 ^5 ^12 dripstone_block
fill ^14 ^5 ^19 ^14 ^3 ^19 dripstone_block
fill ^15 ^5 ^9 ^16 ^5 ^9 dripstone_block
fill ^15 ^5 ^30 ^15 ^3 ^30 dripstone_block
fill ^15 ^5 ^33 ^16 ^5 ^33 dripstone_block
fill ^16 ^5 ^29 ^18 ^5 ^29 dripstone_block
fill ^17 ^5 ^30 ^19 ^5 ^30 dripstone_block
fill ^18 ^5 ^9 ^19 ^5 ^9 dripstone_block
fill ^18 ^5 ^11 ^18 ^7 ^11 dripstone_block
fill ^18 ^5 ^25 ^18 ^3 ^25 dripstone_block
fill ^18 ^5 ^33 ^18 ^7 ^33 dripstone_block
fill ^19 ^5 ^10 ^19 ^7 ^10 dripstone_block
fill ^20 ^5 ^11 ^25 ^5 ^11 dripstone_block
fill ^20 ^5 ^21 ^20 ^5 ^23 obsidian
fill ^20 ^5 ^31 ^21 ^5 ^31 dripstone_block
fill ^21 ^5 ^9 ^21 ^7 ^9 dripstone_block
setblock ^21 ^5 ^20 obsidian
fill ^21 ^5 ^23 ^22 ^5 ^23 obsidian
fill ^21 ^5 ^24 ^21 ^2 ^24 obsidian
fill ^21 ^5 ^27 ^22 ^5 ^27 dripstone_block
fill ^21 ^5 ^28 ^21 ^3 ^28 dripstone_block
fill ^21 ^5 ^29 ^21 ^5 ^31 dripstone_block
fill ^21 ^5 ^33 ^21 ^7 ^33 dripstone_block
fill ^22 ^5 ^10 ^22 ^7 ^10 dripstone_block
fill ^22 ^5 ^21 ^22 ^5 ^23 obsidian
fill ^22 ^5 ^30 ^23 ^5 ^30 dripstone_block
fill ^23 ^5 ^9 ^24 ^5 ^9 dripstone_block
fill ^23 ^5 ^12 ^32 ^5 ^12 dripstone_block
fill ^23 ^5 ^31 ^25 ^5 ^31 dripstone_block
fill ^23 ^5 ^33 ^24 ^5 ^33 dripstone_block
setblock ^24 ^5 ^26 dripstone_block
fill ^25 ^5 ^13 ^26 ^5 ^13 dripstone_block
fill ^25 ^5 ^28 ^30 ^5 ^28 dripstone_block
fill ^25 ^5 ^29 ^30 ^5 ^29 dripstone_block
fill ^25 ^5 ^30 ^29 ^5 ^30 dripstone_block
fill ^26 ^5 ^9 ^26 ^7 ^9 dripstone_block
fill ^26 ^5 ^33 ^26 ^7 ^33 dripstone_block
setblock ^27 ^5 ^13 obsidian
fill ^27 ^5 ^17 ^31 ^5 ^17 dripstone_block
fill ^27 ^5 ^27 ^30 ^5 ^27 dripstone_block
fill ^27 ^5 ^31 ^29 ^5 ^31 dripstone_block
fill ^28 ^5 ^13 ^31 ^5 ^13 dripstone_block
fill ^28 ^5 ^14 ^30 ^5 ^14 dripstone_block
fill ^28 ^5 ^18 ^31 ^5 ^18 dripstone_block
fill ^29 ^5 ^11 ^29 ^7 ^11 dripstone_block
fill ^29 ^5 ^15 ^30 ^5 ^15 dripstone_block
fill ^29 ^5 ^16 ^32 ^5 ^16 dripstone_block
fill ^29 ^5 ^25 ^29 ^7 ^25 dripstone_block
fill ^30 ^5 ^19 ^32 ^5 ^19 dripstone_block
fill ^30 ^5 ^20 ^32 ^5 ^20 dripstone_block
setblock ^30 ^5 ^22 dripstone_block
fill ^30 ^5 ^24 ^31 ^5 ^24 dripstone_block
fill ^30 ^5 ^26 ^32 ^5 ^26 dripstone_block
fill ^31 ^5 ^11 ^32 ^5 ^11 dripstone_block
setblock ^31 ^5 ^15 magma
fill ^31 ^5 ^23 ^31 ^2 ^23 dripstone_block
fill ^31 ^5 ^27 ^31 ^5 ^28 magma
fill ^31 ^5 ^31 ^31 ^7 ^31 dripstone_block
fill ^32 ^5 ^15 ^32 ^8 ^15 dripstone_block
fill ^32 ^5 ^22 ^32 ^5 ^24 dripstone_block
fill ^32 ^5 ^27 ^32 ^6 ^27 dripstone_block
fill ^32 ^5 ^28 ^32 ^6 ^28 dripstone_block
fill ^32 ^5 ^29 ^32 ^6 ^29 dripstone_block
fill ^34 ^5 ^14 ^34 ^7 ^14 dripstone_block
fill ^34 ^5 ^20 ^34 ^8 ^20 dripstone_block
setblock ^34 ^5 ^23 dripstone_block
fill ^34 ^5 ^28 ^34 ^8 ^28 dripstone_block
setblock ^2 ^6 ^32 dripstone_block
fill ^3 ^6 ^31 ^3 ^8 ^31 dripstone_block
fill ^4 ^6 ^29 ^9 ^6 ^29 dripstone_block
fill ^4 ^6 ^30 ^5 ^6 ^30 dripstone_block
fill ^5 ^6 ^28 ^8 ^6 ^28 dripstone_block
fill ^6 ^6 ^27 ^9 ^6 ^27 dripstone_block
fill ^7 ^6 ^26 ^9 ^6 ^26 dripstone_block
fill ^9 ^6 ^30 ^10 ^6 ^30 dripstone_block
fill ^9 ^6 ^31 ^9 ^6 ^32 dripstone_block
setblock ^10 ^6 ^8 dripstone_block
fill ^10 ^6 ^14 ^10 ^8 ^14 dripstone_block
fill ^10 ^6 ^32 ^10 ^7 ^32 dripstone_block
fill ^10 ^6 ^33 ^10 ^8 ^33 dripstone_block
setblock ^11 ^6 ^27 dripstone_block
fill ^11 ^6 ^31 ^17 ^6 ^31 dripstone_block
fill ^12 ^6 ^11 ^18 ^6 ^11 dripstone_block
fill ^12 ^6 ^14 ^12 ^8 ^14 dripstone_block
fill ^12 ^6 ^15 ^13 ^6 ^15 dripstone_block
fill ^12 ^6 ^16 ^12 ^8 ^16 dripstone_block
fill ^12 ^6 ^18 ^12 ^8 ^18 dripstone_block
fill ^12 ^6 ^20 ^12 ^3 ^20 dripstone_block
fill ^12 ^6 ^21 ^12 ^8 ^21 dripstone_block
fill ^12 ^6 ^23 ^13 ^6 ^23 dripstone_block
fill ^12 ^6 ^25 ^12 ^8 ^25 dripstone_block
fill ^12 ^6 ^26 ^12 ^6 ^18 dripstone_block
fill ^13 ^6 ^17 ^14 ^6 ^17 dripstone_block
setblock ^13 ^6 ^27 dripstone_block
fill ^14 ^6 ^12 ^15 ^6 ^12 dripstone_block
fill ^15 ^6 ^9 ^16 ^6 ^9 dripstone_block
fill ^15 ^6 ^33 ^16 ^6 ^33 dripstone_block
fill ^17 ^6 ^30 ^18 ^6 ^30 dripstone_block
fill ^18 ^6 ^9 ^18 ^7 ^9 dripstone_block
fill ^19 ^6 ^31 ^21 ^6 ^31 dripstone_block
fill ^20 ^6 ^11 ^21 ^6 ^11 dripstone_block
setblock ^21 ^6 ^29 obsidian
fill ^21 ^6 ^30 ^23 ^6 ^30 dripstone_block
fill ^23 ^6 ^9 ^24 ^6 ^9 dripstone_block
fill ^23 ^6 ^11 ^32 ^6 ^11 dripstone_block
fill ^23 ^6 ^12 ^25 ^6 ^12 dripstone_block
fill ^23 ^6 ^31 ^25 ^6 ^31 dripstone_block
fill ^23 ^6 ^33 ^24 ^6 ^33 dripstone_block
fill ^26 ^6 ^30 ^26 ^7 ^30 dripstone_block
fill ^27 ^6 ^12 ^32 ^6 ^12 dripstone_block
fill ^27 ^6 ^28 ^27 ^6 ^29 dripstone_block
fill ^27 ^6 ^31 ^28 ^6 ^31 dripstone_block
fill ^28 ^6 ^14 ^28 ^7 ^14 dripstone_block
setblock ^28 ^6 ^27 dripstone_block
fill ^28 ^6 ^29 ^32 ^6 ^29 dripstone_block
fill ^29 ^6 ^9 ^29 ^8 ^9 dripstone_block
fill ^29 ^6 ^13 ^30 ^6 ^13 dripstone_block
fill ^29 ^6 ^18 ^32 ^6 ^18 dripstone_block
setblock ^29 ^6 ^27 obsidian
fill ^29 ^6 ^28 ^30 ^6 ^28 dripstone_block
fill ^29 ^6 ^30 ^30 ^6 ^30 dripstone_block
setblock ^29 ^6 ^31 magma
fill ^29 ^6 ^33 ^29 ^7 ^33 dripstone_block
fill ^30 ^6 ^15 ^30 ^6 ^16 dripstone_block
fill ^30 ^6 ^19 ^32 ^6 ^19 dripstone_block
fill ^30 ^6 ^20 ^32 ^6 ^20 dripstone_block
fill ^30 ^6 ^26 ^32 ^6 ^26 dripstone_block
fill ^30 ^6 ^27 ^30 ^6 ^26 dripstone_block
fill ^30 ^6 ^31 ^30 ^8 ^31 dripstone_block
fill ^31 ^6 ^9 ^34 ^6 ^9 dripstone_block
setblock ^31 ^6 ^13 lava
fill ^31 ^6 ^14 ^32 ^6 ^14 dripstone_block
fill ^31 ^6 ^16 ^32 ^6 ^16 dripstone_block
fill ^31 ^6 ^17 ^31 ^7 ^17 dripstone_block
fill ^31 ^6 ^22 ^32 ^6 ^22 dripstone_block
fill ^31 ^6 ^24 ^32 ^6 ^24 dripstone_block
fill ^31 ^6 ^25 ^32 ^6 ^25 dripstone_block
fill ^31 ^6 ^33 ^32 ^6 ^33 dripstone_block
fill ^32 ^6 ^13 ^32 ^8 ^13 dripstone_block
fill ^32 ^6 ^21 ^32 ^8 ^21 dripstone_block
setblock ^32 ^6 ^23 dripstone_block
fill ^34 ^6 ^12 ^34 ^8 ^12 dripstone_block
fill ^34 ^6 ^15 ^34 ^8 ^15 dripstone_block
fill ^34 ^6 ^17 ^34 ^8 ^17 dripstone_block
fill ^34 ^6 ^18 ^34 ^8 ^18 dripstone_block
fill ^34 ^6 ^22 ^34 ^8 ^22 dripstone_block
fill ^34 ^6 ^23 ^34 ^7 ^23 dripstone_block
fill ^34 ^6 ^25 ^34 ^7 ^25 dripstone_block
fill ^34 ^6 ^26 ^34 ^7 ^26 dripstone_block
fill ^34 ^6 ^30 ^34 ^7 ^30 dripstone_block
fill ^1 ^7 ^8 ^1 ^8 ^8 dripstone_block
fill ^1 ^7 ^14 ^1 ^8 ^14 dripstone_block
fill ^4 ^7 ^29 ^7 ^7 ^29 dripstone_block
fill ^4 ^7 ^30 ^5 ^7 ^30 dripstone_block
fill ^5 ^7 ^28 ^6 ^7 ^28 dripstone_block
fill ^6 ^7 ^27 ^8 ^7 ^27 dripstone_block
setblock ^8 ^7 ^28 dripstone_block
fill ^8 ^7 ^30 ^8 ^7 ^32 dripstone_block
setblock ^9 ^7 ^26 dripstone_block
setblock ^9 ^7 ^32 dripstone_block
fill ^10 ^7 ^8 ^10 ^7 ^9 magma
fill ^10 ^7 ^11 ^11 ^7 ^11 dripstone_block
fill ^10 ^7 ^19 ^11 ^7 ^19 dripstone_block
fill ^11 ^7 ^10 ^33 ^7 ^10 dripstone_block
fill ^11 ^7 ^12 ^11 ^8 ^12 dripstone_block
fill ^11 ^7 ^13 ^11 ^8 ^13 dripstone_block
fill ^11 ^7 ^14 ^11 ^8 ^14 dripstone_block
fill ^11 ^7 ^16 ^11 ^8 ^16 dripstone_block
fill ^11 ^7 ^17 ^13 ^7 ^17 dripstone_block
fill ^11 ^7 ^20 ^11 ^8 ^20 dripstone_block
fill ^11 ^7 ^22 ^11 ^8 ^22 dripstone_block
fill ^11 ^7 ^23 ^11 ^8 ^23 dripstone_block
fill ^11 ^7 ^24 ^11 ^8 ^24 dripstone_block
fill ^11 ^7 ^32 ^18 ^7 ^32 dripstone_block
fill ^12 ^7 ^9 ^12 ^8 ^9 dripstone_block
fill ^12 ^7 ^15 ^12 ^4 ^15 dripstone_block
setblock ^12 ^7 ^31 dripstone_block
setblock ^12 ^7 ^33 dripstone_block
fill ^15 ^7 ^9 ^18 ^7 ^9 dripstone_block
fill ^15 ^7 ^11 ^18 ^7 ^11 dripstone_block
fill ^15 ^7 ^31 ^15 ^8 ^31 dripstone_block
fill ^15 ^7 ^33 ^16 ^7 ^33 dripstone_block
fill ^18 ^7 ^30 ^18 ^7 ^33 dripstone_block
fill ^19 ^7 ^31 ^19 ^8 ^31 dripstone_block
fill ^20 ^7 ^9 ^20 ^8 ^9 dripstone_block
fill ^20 ^7 ^32 ^21 ^7 ^32 dripstone_block
fill ^20 ^7 ^33 ^20 ^8 ^33 dripstone_block
setblock ^21 ^7 ^31 dripstone_block
fill ^22 ^7 ^30 ^23 ^7 ^30 dripstone_block
fill ^23 ^7 ^9 ^24 ^7 ^9 dripstone_block
fill ^23 ^7 ^31 ^25 ^7 ^31 dripstone_block
fill ^23 ^7 ^32 ^24 ^7 ^32 dripstone_block
fill ^23 ^7 ^33 ^24 ^7 ^33 dripstone_block
fill ^26 ^7 ^0 ^26 ^8 ^0 dripstone_block
fill ^26 ^7 ^11 ^34 ^7 ^11 dripstone_block
fill ^26 ^7 ^32 ^33 ^7 ^32 dripstone_block
fill ^26 ^7 ^42 ^26 ^8 ^42 dripstone_block
fill ^27 ^7 ^9 ^27 ^8 ^9 dripstone_block
fill ^27 ^7 ^31 ^28 ^7 ^31 dripstone_block
setblock ^27 ^7 ^33 dripstone_block
fill ^28 ^7 ^12 ^34 ^7 ^12 dripstone_block
fill ^29 ^7 ^13 ^30 ^7 ^13 dripstone_block
fill ^29 ^7 ^29 ^30 ^7 ^29 dripstone_block
fill ^29 ^7 ^30 ^34 ^7 ^30 dripstone_block
fill ^30 ^7 ^9 ^32 ^7 ^9 dripstone_block
fill ^30 ^7 ^19 ^31 ^7 ^19 dripstone_block
fill ^30 ^7 ^20 ^30 ^5 ^20 dripstone_block
setblock ^30 ^7 ^26 dripstone_block
fill ^30 ^7 ^33 ^32 ^7 ^33 dripstone_block
fill ^31 ^7 ^14 ^34 ^7 ^14 dripstone_block
fill ^31 ^7 ^18 ^32 ^7 ^18 dripstone_block
fill ^31 ^7 ^24 ^33 ^7 ^24 dripstone_block
fill ^31 ^7 ^25 ^33 ^7 ^25 dripstone_block
fill ^32 ^7 ^17 ^34 ^7 ^17 dripstone_block
fill ^32 ^7 ^22 ^34 ^7 ^22 dripstone_block
fill ^32 ^7 ^26 ^34 ^7 ^26 dripstone_block
fill ^32 ^7 ^31 ^33 ^7 ^31 dripstone_block
fill ^32 ^7 ^42 ^32 ^8 ^42 dripstone_block
setblock ^33 ^7 ^9 magma
fill ^33 ^7 ^13 ^33 ^8 ^13 dripstone_block
fill ^33 ^7 ^15 ^33 ^8 ^15 dripstone_block
fill ^33 ^7 ^16 ^33 ^8 ^16 dripstone_block
fill ^33 ^7 ^19 ^33 ^8 ^19 dripstone_block
fill ^33 ^7 ^20 ^33 ^7 ^19 dripstone_block
fill ^33 ^7 ^23 ^33 ^8 ^23 dripstone_block
fill ^33 ^7 ^27 ^33 ^7 ^32 dripstone_block
fill ^34 ^7 ^9 ^34 ^8 ^9 dripstone_block
setblock ^34 ^7 ^29 dripstone_block
fill ^34 ^7 ^33 ^34 ^8 ^33 dripstone_block
fill ^1 ^8 ^3 ^2 ^8 ^3 dripstone_block
fill ^1 ^8 ^9 ^3 ^8 ^9 dripstone_block
fill ^2 ^8 ^4 ^3 ^8 ^4 dripstone_block
fill ^2 ^8 ^14 ^3 ^8 ^14 dripstone_block
setblock ^3 ^8 ^2 dripstone_block
fill ^3 ^8 ^5 ^4 ^8 ^5 dripstone_block
fill ^3 ^8 ^10 ^4 ^8 ^10 dripstone_block
fill ^3 ^8 ^15 ^6 ^8 ^15 dripstone_block
fill ^3 ^8 ^17 ^5 ^8 ^17 dripstone_block
setblock ^3 ^8 ^24 dripstone_block
fill ^4 ^8 ^3 ^5 ^8 ^3 dripstone_block
fill ^4 ^8 ^6 ^5 ^8 ^6 dripstone_block
fill ^4 ^8 ^23 ^5 ^8 ^23 dripstone_block
fill ^4 ^8 ^27 ^5 ^8 ^27 dripstone_block
fill ^4 ^8 ^29 ^6 ^8 ^29 dripstone_block
fill ^4 ^8 ^30 ^5 ^8 ^30 dripstone_block
setblock ^5 ^8 ^4 dripstone_block
fill ^5 ^8 ^7 ^17 ^8 ^7 dripstone_block
fill ^5 ^8 ^11 ^6 ^8 ^11 dripstone_block
fill ^5 ^8 ^18 ^10 ^8 ^18 dripstone_block
fill ^5 ^8 ^20 ^11 ^8 ^20 dripstone_block
fill ^5 ^8 ^22 ^11 ^8 ^22 dripstone_block
fill ^5 ^8 ^26 ^8 ^8 ^26 dripstone_block
fill ^5 ^8 ^28 ^5 ^6 ^28 dripstone_block
setblock ^5 ^8 ^33 dripstone_block
setblock ^6 ^8 ^5 dripstone_block
fill ^6 ^8 ^12 ^9 ^8 ^12 dripstone_block
fill ^6 ^8 ^16 ^9 ^8 ^16 dripstone_block
setblock ^6 ^8 ^32 dripstone_block
fill ^7 ^8 ^6 ^15 ^8 ^6 dripstone_block
fill ^7 ^8 ^8 ^9 ^8 ^8 dripstone_block
fill ^7 ^8 ^14 ^8 ^8 ^14 dripstone_block
fill ^7 ^8 ^30 ^7 ^8 ^31 dripstone_block
fill ^7 ^8 ^35 ^8 ^8 ^35 dripstone_block
fill ^7 ^8 ^36 ^7 ^8 ^35 dripstone_block
fill ^8 ^8 ^5 ^11 ^8 ^5 dripstone_block
fill ^8 ^8 ^9 ^9 ^8 ^9 dripstone_block
fill ^8 ^8 ^11 ^11 ^8 ^11 dripstone_block
fill ^8 ^8 ^13 ^11 ^8 ^13 dripstone_block
fill ^8 ^8 ^15 ^9 ^8 ^15 dripstone_block
fill ^8 ^8 ^25 ^9 ^8 ^25 dripstone_block
setblock ^8 ^8 ^32 dripstone_block
fill ^8 ^8 ^34 ^9 ^8 ^34 dripstone_block
fill ^8 ^8 ^39 ^9 ^8 ^39 dripstone_block
fill ^9 ^8 ^10 ^18 ^8 ^10 dripstone_block
setblock ^9 ^8 ^17 dripstone_block
fill ^9 ^8 ^23 ^9 ^8 ^25 dripstone_block
setblock ^9 ^8 ^33 dripstone_block
fill ^9 ^8 ^38 ^10 ^8 ^38 dripstone_block
setblock ^10 ^8 ^4 dripstone_block
fill ^10 ^8 ^19 ^11 ^8 ^19 dripstone_block
setblock ^10 ^8 ^24 dripstone_block
fill ^10 ^8 ^36 ^11 ^8 ^36 dripstone_block
fill ^10 ^8 ^37 ^10 ^8 ^36 dripstone_block
fill ^11 ^8 ^8 ^14 ^8 ^8 dripstone_block
fill ^11 ^8 ^9 ^11 ^8 ^5 dripstone_block
setblock ^11 ^8 ^15 dripstone_block
fill ^11 ^8 ^17 ^12 ^8 ^17 dripstone_block
setblock ^11 ^8 ^21 dripstone_block
fill ^11 ^8 ^32 ^15 ^8 ^32 dripstone_block
fill ^11 ^8 ^33 ^11 ^8 ^32 dripstone_block
fill ^11 ^8 ^35 ^15 ^8 ^35 dripstone_block
fill ^12 ^8 ^34 ^14 ^8 ^34 dripstone_block
fill ^13 ^8 ^2 ^13 ^8 ^3 dripstone_block
fill ^13 ^8 ^5 ^15 ^8 ^5 dripstone_block
fill ^14 ^8 ^3 ^14 ^8 ^10 dripstone_block
setblock ^14 ^8 ^33 dripstone_block
fill ^14 ^8 ^37 ^15 ^8 ^37 dripstone_block
fill ^14 ^8 ^38 ^14 ^8 ^39 dripstone_block
fill ^15 ^8 ^11 ^17 ^8 ^11 dripstone_block
setblock ^15 ^8 ^36 dripstone_block
setblock ^16 ^8 ^8 dripstone_block
fill ^16 ^8 ^33 ^16 ^8 ^34 dripstone_block
fill ^17 ^8 ^5 ^17 ^8 ^7 dripstone_block
setblock ^17 ^8 ^9 dripstone_block
fill ^17 ^8 ^32 ^18 ^8 ^32 dripstone_block
fill ^17 ^8 ^34 ^19 ^8 ^34 dripstone_block
fill ^17 ^8 ^35 ^17 ^8 ^34 dripstone_block
fill ^18 ^8 ^8 ^21 ^8 ^8 dripstone_block
setblock ^18 ^8 ^31 dripstone_block
fill ^19 ^8 ^5 ^19 ^8 ^9 dripstone_block
setblock ^19 ^8 ^33 dripstone_block
setblock ^19 ^8 ^35 dripstone_block
fill ^20 ^8 ^10 ^21 ^8 ^10 dripstone_block
fill ^20 ^8 ^32 ^25 ^8 ^32 dripstone_block
fill ^21 ^8 ^0 ^21 ^8 ^8 dripstone_block
fill ^21 ^8 ^34 ^21 ^8 ^37 dripstone_block
fill ^22 ^8 ^6 ^23 ^8 ^6 dripstone_block
fill ^22 ^8 ^7 ^23 ^8 ^7 dripstone_block
setblock ^22 ^8 ^8 obsidian
setblock ^22 ^8 ^9 dripstone_block
setblock ^22 ^8 ^31 dripstone_block
fill ^22 ^8 ^33 ^23 ^8 ^33 dripstone_block
fill ^23 ^8 ^3 ^23 ^8 ^8 dripstone_block
fill ^23 ^8 ^10 ^36 ^8 ^10 dripstone_block
fill ^23 ^8 ^34 ^36 ^8 ^34 dripstone_block
fill ^23 ^8 ^35 ^23 ^8 ^38 dripstone_block
fill ^24 ^8 ^8 ^26 ^8 ^8 dripstone_block
fill ^25 ^8 ^3 ^26 ^8 ^3 dripstone_block
fill ^25 ^8 ^4 ^25 ^8 ^8 dripstone_block
setblock ^25 ^8 ^33 dripstone_block
fill ^25 ^8 ^35 ^25 ^8 ^39 dripstone_block
fill ^26 ^8 ^1 ^26 ^8 ^3 dripstone_block
fill ^26 ^8 ^7 ^28 ^8 ^7 dripstone_block
fill ^26 ^8 ^11 ^28 ^8 ^11 dripstone_block
setblock ^26 ^8 ^31 dripstone_block
fill ^26 ^8 ^39 ^26 ^8 ^42 dripstone_block
fill ^27 ^8 ^5 ^27 ^8 ^7 dripstone_block
fill ^27 ^8 ^35 ^32 ^8 ^35 dripstone_block
fill ^27 ^8 ^36 ^27 ^8 ^37 dripstone_block
fill ^28 ^8 ^8 ^39 ^8 ^8 dripstone_block
fill ^28 ^8 ^9 ^28 ^8 ^7 dripstone_block
setblock ^28 ^8 ^33 dripstone_block
fill ^29 ^8 ^5 ^29 ^8 ^6 dripstone_block
fill ^29 ^8 ^36 ^29 ^8 ^37 dripstone_block
fill ^30 ^8 ^7 ^34 ^8 ^7 dripstone_block
fill ^30 ^8 ^9 ^32 ^8 ^9 dripstone_block
setblock ^30 ^8 ^11 dripstone_block
fill ^30 ^8 ^30 ^31 ^8 ^30 dripstone_block
fill ^30 ^8 ^37 ^32 ^8 ^37 dripstone_block
fill ^30 ^8 ^38 ^30 ^8 ^39 dripstone_block
setblock ^31 ^8 ^6 dripstone_block
fill ^31 ^8 ^14 ^33 ^8 ^14 dripstone_block
fill ^31 ^8 ^25 ^35 ^8 ^25 dripstone_block
setblock ^31 ^8 ^36 dripstone_block
fill ^31 ^8 ^39 ^31 ^8 ^41 dripstone_block
fill ^32 ^8 ^5 ^36 ^8 ^5 dripstone_block
fill ^32 ^8 ^17 ^35 ^8 ^17 dripstone_block
fill ^32 ^8 ^18 ^39 ^8 ^18 dripstone_block
setblock ^32 ^8 ^38 dripstone_block
setblock ^32 ^8 ^41 dripstone_block
fill ^33 ^8 ^6 ^35 ^8 ^6 dripstone_block
fill ^33 ^8 ^11 ^34 ^8 ^11 dripstone_block
fill ^33 ^8 ^12 ^33 ^8 ^10 dripstone_block
setblock ^33 ^8 ^20 obsidian
fill ^33 ^8 ^21 ^34 ^8 ^21 dripstone_block
fill ^33 ^8 ^22 ^33 ^8 ^21 dripstone_block
setblock ^33 ^8 ^24 dripstone_block
setblock ^33 ^8 ^33 dripstone_block
fill ^33 ^8 ^39 ^33 ^8 ^40 dripstone_block
fill ^34 ^8 ^13 ^36 ^8 ^13 dripstone_block
setblock ^34 ^8 ^19 dripstone_block
fill ^34 ^8 ^27 ^35 ^8 ^27 dripstone_block
fill ^34 ^8 ^31 ^36 ^8 ^31 dripstone_block
fill ^34 ^8 ^32 ^35 ^8 ^32 dripstone_block
setblock ^34 ^8 ^35 dripstone_block
fill ^35 ^8 ^9 ^37 ^8 ^9 dripstone_block
fill ^35 ^8 ^15 ^35 ^8 ^18 dripstone_block
fill ^35 ^8 ^20 ^37 ^8 ^20 dripstone_block
fill ^35 ^8 ^22 ^41 ^8 ^22 dripstone_block
setblock ^35 ^8 ^26 dripstone_block
fill ^35 ^8 ^28 ^38 ^8 ^28 dripstone_block
fill ^35 ^8 ^29 ^36 ^8 ^29 dripstone_block
fill ^35 ^8 ^30 ^35 ^8 ^25 dripstone_block
fill ^35 ^8 ^33 ^36 ^8 ^33 dripstone_block
fill ^36 ^8 ^4 ^37 ^8 ^4 dripstone_block
fill ^36 ^8 ^12 ^37 ^8 ^12 dripstone_block
fill ^36 ^8 ^14 ^37 ^8 ^14 dripstone_block
fill ^36 ^8 ^16 ^38 ^8 ^16 dripstone_block
fill ^36 ^8 ^35 ^37 ^8 ^35 dripstone_block
fill ^37 ^8 ^3 ^38 ^8 ^3 dripstone_block
fill ^37 ^8 ^7 ^39 ^8 ^7 dripstone_block
fill ^37 ^8 ^11 ^38 ^8 ^11 dripstone_block
fill ^37 ^8 ^36 ^38 ^8 ^36 dripstone_block
setblock ^38 ^8 ^2 dripstone_block
fill ^38 ^8 ^10 ^39 ^8 ^10 dripstone_block
fill ^38 ^8 ^15 ^41 ^8 ^15 dripstone_block
fill ^38 ^8 ^29 ^39 ^8 ^29 dripstone_block
fill ^38 ^8 ^37 ^39 ^8 ^37 dripstone_block
fill ^39 ^8 ^6 ^40 ^8 ^6 dripstone_block
fill ^39 ^8 ^17 ^41 ^8 ^17 dripstone_block
setblock ^39 ^8 ^38 dripstone_block
setblock ^40 ^8 ^5 dripstone_block
fill ^41 ^8 ^14 ^43 ^8 ^14 dripstone_block